{
 "cells": [
  {
   "cell_type": "code",
   "execution_count": 1,
   "metadata": {},
   "outputs": [
    {
     "name": "stdout",
     "output_type": "stream",
     "text": [
      "Unexpected exception formatting exception. Falling back to standard exception\n"
     ]
    },
    {
     "name": "stderr",
     "output_type": "stream",
     "text": [
      "Traceback (most recent call last):\n",
      "  File \"c:\\Users\\ASUS\\AppData\\Local\\Programs\\Python\\Python310\\lib\\site-packages\\IPython\\core\\interactiveshell.py\", line 3508, in run_code\n",
      "    exec(code_obj, self.user_global_ns, self.user_ns)\n",
      "  File \"C:\\Users\\ASUS\\AppData\\Local\\Temp\\ipykernel_24600\\1642365271.py\", line 3, in <module>\n",
      "    from app.disaster_predictor import DisasterPredictorApp\n",
      "ModuleNotFoundError: No module named 'app'\n",
      "\n",
      "During handling of the above exception, another exception occurred:\n",
      "\n",
      "Traceback (most recent call last):\n",
      "  File \"c:\\Users\\ASUS\\AppData\\Local\\Programs\\Python\\Python310\\lib\\site-packages\\IPython\\core\\interactiveshell.py\", line 2105, in showtraceback\n",
      "    stb = self.InteractiveTB.structured_traceback(\n",
      "  File \"c:\\Users\\ASUS\\AppData\\Local\\Programs\\Python\\Python310\\lib\\site-packages\\IPython\\core\\ultratb.py\", line 1428, in structured_traceback\n",
      "    return FormattedTB.structured_traceback(\n",
      "  File \"c:\\Users\\ASUS\\AppData\\Local\\Programs\\Python\\Python310\\lib\\site-packages\\IPython\\core\\ultratb.py\", line 1319, in structured_traceback\n",
      "    return VerboseTB.structured_traceback(\n",
      "  File \"c:\\Users\\ASUS\\AppData\\Local\\Programs\\Python\\Python310\\lib\\site-packages\\IPython\\core\\ultratb.py\", line 1172, in structured_traceback\n",
      "    formatted_exception = self.format_exception_as_a_whole(etype, evalue, etb, number_of_lines_of_context,\n",
      "  File \"c:\\Users\\ASUS\\AppData\\Local\\Programs\\Python\\Python310\\lib\\site-packages\\IPython\\core\\ultratb.py\", line 1087, in format_exception_as_a_whole\n",
      "    frames.append(self.format_record(record))\n",
      "  File \"c:\\Users\\ASUS\\AppData\\Local\\Programs\\Python\\Python310\\lib\\site-packages\\IPython\\core\\ultratb.py\", line 969, in format_record\n",
      "    frame_info.lines, Colors, self.has_colors, lvals\n",
      "  File \"c:\\Users\\ASUS\\AppData\\Local\\Programs\\Python\\Python310\\lib\\site-packages\\IPython\\core\\ultratb.py\", line 792, in lines\n",
      "    return self._sd.lines\n",
      "  File \"c:\\Users\\ASUS\\AppData\\Local\\Programs\\Python\\Python310\\lib\\site-packages\\stack_data\\utils.py\", line 144, in cached_property_wrapper\n",
      "    value = obj.__dict__[self.func.__name__] = self.func(obj)\n",
      "  File \"c:\\Users\\ASUS\\AppData\\Local\\Programs\\Python\\Python310\\lib\\site-packages\\stack_data\\core.py\", line 734, in lines\n",
      "    pieces = self.included_pieces\n",
      "  File \"c:\\Users\\ASUS\\AppData\\Local\\Programs\\Python\\Python310\\lib\\site-packages\\stack_data\\utils.py\", line 144, in cached_property_wrapper\n",
      "    value = obj.__dict__[self.func.__name__] = self.func(obj)\n",
      "  File \"c:\\Users\\ASUS\\AppData\\Local\\Programs\\Python\\Python310\\lib\\site-packages\\stack_data\\core.py\", line 677, in included_pieces\n",
      "    scope_pieces = self.scope_pieces\n",
      "  File \"c:\\Users\\ASUS\\AppData\\Local\\Programs\\Python\\Python310\\lib\\site-packages\\stack_data\\utils.py\", line 144, in cached_property_wrapper\n",
      "    value = obj.__dict__[self.func.__name__] = self.func(obj)\n",
      "  File \"c:\\Users\\ASUS\\AppData\\Local\\Programs\\Python\\Python310\\lib\\site-packages\\stack_data\\core.py\", line 614, in scope_pieces\n",
      "    scope_start, scope_end = self.source.line_range(self.scope)\n",
      "  File \"c:\\Users\\ASUS\\AppData\\Local\\Programs\\Python\\Python310\\lib\\site-packages\\stack_data\\core.py\", line 178, in line_range\n",
      "    return line_range(self.asttext(), node)\n",
      "  File \"c:\\Users\\ASUS\\AppData\\Local\\Programs\\Python\\Python310\\lib\\site-packages\\executing\\executing.py\", line 428, in asttext\n",
      "    self._asttext = ASTText(self.text, tree=self.tree, filename=self.filename)\n",
      "  File \"c:\\Users\\ASUS\\AppData\\Local\\Programs\\Python\\Python310\\lib\\site-packages\\asttokens\\asttokens.py\", line 307, in __init__\n",
      "    super(ASTText, self).__init__(source_text, filename)\n",
      "  File \"c:\\Users\\ASUS\\AppData\\Local\\Programs\\Python\\Python310\\lib\\site-packages\\asttokens\\asttokens.py\", line 44, in __init__\n",
      "    source_text = six.ensure_text(source_text)\n",
      "AttributeError: module 'six' has no attribute 'ensure_text'\n"
     ]
    }
   ],
   "source": [
    "import sys\n",
    "sys.path.append('D:/google_hackathon/project/VoilaDisasterPredictor/app')\n",
    "from app.disaster_predictor import DisasterPredictorApp\n",
    "app = DisasterPredictorApp()"
   ]
  },
  {
   "cell_type": "code",
   "execution_count": null,
   "metadata": {},
   "outputs": [],
   "source": []
  }
 ],
 "metadata": {
  "kernelspec": {
   "display_name": "Python 3",
   "language": "python",
   "name": "python3"
  },
  "language_info": {
   "codemirror_mode": {
    "name": "ipython",
    "version": 3
   },
   "file_extension": ".py",
   "mimetype": "text/x-python",
   "name": "python",
   "nbconvert_exporter": "python",
   "pygments_lexer": "ipython3",
   "version": "3.10.4"
  },
  "orig_nbformat": 4
 },
 "nbformat": 4,
 "nbformat_minor": 2
}
